--TEST--
awaitAll() - iterator exception in next() method
--FILE--
<?php

use function Async\spawn;
use function Async\awaitAll;

echo "start\n";

class FailingNextIterator implements Iterator
{
    private $position = 0;
    private $data = ['first', 'second'];
    
    public function rewind(): void {
        $this->position = 0;
    }
    
    public function current(): mixed {
        return spawn(function() {
            return $this->data[$this->position];
        });
    }
    
    public function key(): mixed {
        return $this->position;
    }
    
    public function next(): void {
        $this->position++;
        if ($this->position === 1) {
            throw new \RuntimeException("Iterator next() failed");
        }
    }
    
    public function valid(): bool {
        return isset($this->data[$this->position]);
    }
}

try {
    $results = awaitAll(new FailingNextIterator());
    echo "ERROR: Should have thrown exception\n";
} catch (\RuntimeException $e) {
    echo "Caught next() exception: " . $e->getMessage() . "\n";
} catch (Throwable $e) {
    echo "Caught exception: " . get_class($e) . ": " . $e->getMessage() . "\n";
}

echo "end\n";

?>
--EXPECT--
start
Caught next() exception: Iterator next() failed
end